Workbook

Sheet Fact_Sales
A1: Date | B1: CustomerID | C1: ProductID | D1: Revenue | E1: Quantity | F1: Discount | G1: ActualCost | H1: CalculatedProfit | I1: Month | J1: COGS
A2: 2024-01-04 | B2: CUST-008 | C2: PRD-001 | D2: 14763 | E2: 37 | F2: 0 | G2: {=IFERROR(--SUBSTITUTE(INDEX(Product_Costing!$I$2:$I$201,MATCH(1,(Product_Costing!$B$2:$B$201=Fact_Sales[[#This Row],[ProductID]])*(Product_Costing!$C$2:$C$201=DATE(YEAR(Fact_Sales[[#This Row],[Date]]),MONTH(Fact_Sales[[#This Row],[Date]]),1)),0))&""," USD",""),"")} -> 186.97 | H2: =IF(Fact_Sales[[#This Row],[Revenue]]="","",IFERROR(--SUBSTITUTE(Fact_Sales[[#This Row],[Revenue]]&""," USD",""),Fact_Sales[[#This Row],[Revenue]])-Fact_Sales[[#This Row],[Quantity]]*Fact_Sales[[#This Row],[ActualCost]]) -> 7845.11 | I2: =EOMONTH(Fact_Sales[[#This Row],[Date]],-1)+1 -> 45292 | J2: =IFERROR(Fact_Sales[[#This Row],[Quantity]]*Fact_Sales[[#This Row],[ActualCost]],0) -> 6917.89
A3: 2024-01-19 | B3: CUST-007 | C3: PRD-001 | D3: 61725.3 | E3: 182 | F3: 0.15 | G3: {=IFERROR(--SUBSTITUTE(INDEX(Product_Costing!$I$2:$I$201,MATCH(1,(Product_Costing!$B$2:$B$201=Fact_Sales[[#This Row],[ProductID]])*(Product_Costing!$C$2:$C$201=DATE(YEAR(Fact_Sales[[#This Row],[Date]]),MONTH(Fact_Sales[[#This Row],[Date]]),1)),0))&""," USD",""),"")} -> 186.97 | H3: =IF(Fact_Sales[[#This Row],[Revenue]]="","",IFERROR(--SUBSTITUTE(Fact_Sales[[#This Row],[Revenue]]&""," USD",""),Fact_Sales[[#This Row],[Revenue]])-Fact_Sales[[#This Row],[Quantity]]*Fact_Sales[[#This Row],[ActualCost]]) -> 27696.76 | I3: =EOMONTH(Fact_Sales[[#This Row],[Date]],-1)+1 -> 45292 | J3: =IFERROR(Fact_Sales[[#This Row],[Quantity]]*Fact_Sales[[#This Row],[ActualCost]],0) -> 34028.54
A4: 2024-01-01 | B4: CUST-008 | C4: PRD-001 | D4: 46623.15 | E4: 123 | F4: 0.05 | G4: {=IFERROR(--SUBSTITUTE(INDEX(Product_Costing!$I$2:$I$201,MATCH(1,(Product_Costing!$B$2:$B$201=Fact_Sales[[#This Row],[ProductID]])*(Product_Costing!$C$2:$C$201=DATE(YEAR(Fact_Sales[[#This Row],[Date]]),MONTH(Fact_Sales[[#This Row],[Date]]),1)),0))&""," USD",""),"")} -> 186.97 | H4: =IF(Fact_Sales[[#This Row],[Revenue]]="","",IFERROR(--SUBSTITUTE(Fact_Sales[[#This Row],[Revenue]]&""," USD",""),Fact_Sales[[#This Row],[Revenue]])-Fact_Sales[[#This Row],[Quantity]]*Fact_Sales[[#This Row],[ActualCost]]) -> 23625.84 | I4: =EOMONTH(Fact_Sales[[#This Row],[Date]],-1)+1 -> 45292 | J4: =IFERROR(Fact_Sales[[#This Row],[Quantity]]*Fact_Sales[[#This Row],[ActualCost]],0) -> 22997.31
A5: 2024-01-12 | B5: CUST-009 | C5: PRD-001 | D5: 69027 | E5: 173 | F5: 0 | G5: {=IFERROR(--SUBSTITUTE(INDEX(Product_Costing!$I$2:$I$201,MATCH(1,(Product_Costing!$B$2:$B$201=Fact_Sales[[#This Row],[ProductID]])*(Product_Costing!$C$2:$C$201=DATE(YEAR(Fact_Sales[[#This Row],[Date]]),MONTH(Fact_Sales[[#This Row],[Date]]),1)),0))&""," USD",""),"")} -> 186.97 | H5: =IF(Fact_Sales[[#This Row],[Revenue]]="","",IFERROR(--SUBSTITUTE(Fact_Sales[[#This Row],[Revenue]]&""," USD",""),Fact_Sales[[#This Row],[Revenue]])-Fact_Sales[[#This Row],[Quantity]]*Fact_Sales[[#This Row],[ActualCost]]) -> 36681.19 | I5: =EOMONTH(Fact_Sales[[#This Row],[Date]],-1)+1 -> 45292 | J5: =IFERROR(Fact_Sales[[#This Row],[Quantity]]*Fact_Sales[[#This Row],[ActualCost]],0) -> 32345.81
A6: 2024-01-26 | B6: CUST-009 | C6: PRD-001 | D6: 68229 | E6: 171 | F6: 0 | G6: {=IFERROR(--SUBSTITUTE(INDEX(Product_Costing!$I$2:$I$201,MATCH(1,(Product_Costing!$B$2:$B$201=Fact_Sales[[#This Row],[ProductID]])*(Product_Costing!$C$2:$C$201=DATE(YEAR(Fact_Sales[[#This Row],[Date]]),MONTH(Fact_Sales[[#This Row],[Date]]),1)),0))&""," USD",""),"")} -> 186.97 | H6: =IF(Fact_Sales[[#This Row],[Revenue]]="","",IFERROR(--SUBSTITUTE(Fact_Sales[[#This Row],[Revenue]]&""," USD",""),Fact_Sales[[#This Row],[Revenue]])-Fact_Sales[[#This Row],[Quantity]]*Fact_Sales[[#This Row],[ActualCost]]) -> 36257.13 | I6: =EOMONTH(Fact_Sales[[#This Row],[Date]],-1)+1 -> 45292 | J6: =IFERROR(Fact_Sales[[#This Row],[Quantity]]*Fact_Sales[[#This Row],[ActualCost]],0) -> 31971.87
A7: 2024-01-01 | B7: CUST-001 | C7: PRD-001 | D7: 46463.55 | E7: 137 | F7: 0.15 | G7: {=IFERROR(--SUBSTITUTE(INDEX(Product_Costing!$I$2:$I$201,MATCH(1,(Product_Costing!$B$2:$B$201=Fact_Sales[[#This Row],[ProductID]])*(Product_Costing!$C$2:$C$201=DATE(YEAR(Fact_Sales[[#This Row],[Date]]),MONTH(Fact_Sales[[#This Row],[Date]]),1)),0))&""," USD",""),"")} -> 186.97 | H7: =IF(Fact_Sales[[#This Row],[Revenue]]="","",IFERROR(--SUBSTITUTE(Fact_Sales[[#This Row],[Revenue]]&""," USD",""),Fact_Sales[[#This Row],[Revenue]])-Fact_Sales[[#This Row],[Quantity]]*Fact_Sales[[#This Row],[ActualCost]]) -> 20848.66 | I7: =EOMONTH(Fact_Sales[[#This Row],[Date]],-1)+1 -> 45292 | J7: =IFERROR(Fact_Sales[[#This Row],[Quantity]]*Fact_Sales[[#This Row],[ActualCost]],0) -> 25614.89
A8: 2024-01-21 | B8: CUST-010 | C8: PRD-001 | D8: 54663 | E8: 137 | F8: 0 | G8: {=IFERROR(--SUBSTITUTE(INDEX(Product_Costing!$I$2:$I$201,MATCH(1,(Product_Costing!$B$2:$B$201=Fact_Sales[[#This Row],[ProductID]])*(Product_Costing!$C$2:$C$201=DATE(YEAR(Fact_Sales[[#This Row],[Date]]),MONTH(Fact_Sales[[#This Row],[Date]]),1)),0))&""," USD",""),"")} -> 186.97 | H8: =IF(Fact_Sales[[#This Row],[Revenue]]="","",IFERROR(--SUBSTITUTE(Fact_Sales[[#This Row],[Revenue]]&""," USD",""),Fact_Sales[[#This Row],[Revenue]])-Fact_Sales[[#This Row],[Quantity]]*Fact_Sales[[#This Row],[ActualCost]]) -> 29048.11 | I8: =EOMONTH(Fact_Sales[[#This Row],[Date]],-1)+1 -> 45292 | J8: =IFERROR(Fact_Sales[[#This Row],[Quantity]]*Fact_Sales[[#This Row],[ActualCost]],0) -> 25614.89
A9: 2024-01-07 | B9: CUST-010 | C9: PRD-002 | D9: 37677.1 | E9: 74 | F9: 0.15 | G9: {=IFERROR(--SUBSTITUTE(INDEX(Product_Costing!$I$2:$I$201,MATCH(1,(Product_Costing!$B$2:$B$201=Fact_Sales[[#This Row],[ProductID]])*(Product_Costing!$C$2:$C$201=DATE(YEAR(Fact_Sales[[#This Row],[Date]]),MONTH(Fact_Sales[[#This Row],[Date]]),1)),0))&""," USD",""),"")} -> 253.51 | H9: =IF(Fact_Sales[[#This Row],[Revenue]]="","",IFERROR(--SUBSTITUTE(Fact_Sales[[#This Row],[Revenue]]&""," USD",""),Fact_Sales[[#This Row],[Revenue]])-Fact_Sales[[#This Row],[Quantity]]*Fact_Sales[[#This Row],[ActualCost]]) -> 18917.36 | I9: =EOMONTH(Fact_Sales[[#This Row],[Date]],-1)+1 -> 45292 | J9: =IFERROR(Fact_Sales[[#This Row],[Quantity]]*Fact_Sales[[#This Row],[ActualCost]],0) -> 18759.74
A10: 2024-01-18 | B10: CUST-007 | C10: PRD-002 | D10: 9584 | E10: 16 | F10: 0 | G10: {=IFERROR(--SUBSTITUTE(INDEX(Product_Costing!$I$2:$I$201,MATCH(1,(Product_Costing!$B$2:$B$201=Fact_Sales[[#This Row],[ProductID]])*(Product_Costing!$C$2:$C$201=DATE(YEAR(Fact_Sales[[#This Row],[Date]]),MONTH(Fact_Sales[[#This Row],[Date]]),1)),0))&""," USD",""),"")} -> 253.51 | H10: =IF(Fact_Sales[[#This Row],[Revenue]]="","",IFERROR(--SUBSTITUTE(Fact_Sales[[#This Row],[Revenue]]&""," USD",""),Fact_Sales[[#This Row],[Revenue]])-Fact_Sales[[#This Row],[Quantity]]*Fact_Sales[[#This Row],[ActualCost]]) -> 5527.84 | I10: =EOMONTH(Fact_Sales[[#This Row],[Date]],-1)+1 -> 45292 | J10: =IFERROR(Fact_Sales[[#This Row],[Quantity]]*Fact_Sales[[#This Row],[ActualCost]],0) -> 4056.16
A11: 2024-01-16 | B11: CUST-013 | C11: PRD-002 | D11: 62625.45 | E11: 123 | F11: 0.15 | G11: {=IFERROR(--SUBSTITUTE(INDEX(Product_Costing!$I$2:$I$201,MATCH(1,(Product_Costing!$B$2:$B$201=Fact_Sales[[#This Row],[ProductID]])*(Product_Costing!$C$2:$C$201=DATE(YEAR(Fact_Sales[[#This Row],[Date]]),MONTH(Fact_Sales[[#This Row],[Date]]),1)),0))&""," USD",""),"")} -> 253.51 | H11: =IF(Fact_Sales[[#This Row],[Revenue]]="","",IFERROR(--SUBSTITUTE(Fact_Sales[[#This Row],[Revenue]]&""," USD",""),Fact_Sales[[#This Row],[Revenue]])-Fact_Sales[[#This Row],[Quantity]]*Fact_Sales[[#This Row],[ActualCost]]) -> 31443.72 | I11: =EOMONTH(Fact_Sales[[#This Row],[Date]],-1)+1 -> 45292 | J11: =IFERROR(Fact_Sales[[#This Row],[Quantity]]*Fact_Sales[[#This Row],[ActualCost]],0) -> 31181.73
A12: 2024-01-20 | B12: CUST-010 | C12: PRD-002 | D12: 41331 | E12: 69 | F12: 0 | G12: {=IFERROR(--SUBSTITUTE(INDEX(Product_Costing!$I$2:$I$201,MATCH(1,(Product_Costing!$B$2:$B$201=Fact_Sales[[#This Row],[ProductID]])*(Product_Costing!$C$2:$C$201=DATE(YEAR(Fact_Sales[[#This Row],[Date]]),MONTH(Fact_Sales[[#This Row],[Date]]),1)),0))&""," USD",""),"")} -> 253.51 | H12: =IF(Fact_Sales[[#This Row],[Revenue]]="","",IFERROR(--SUBSTITUTE(Fact_Sales[[#This Row],[Revenue]]&""," USD",""),Fact_Sales[[#This Row],[Revenue]])-Fact_Sales[[#This Row],[Quantity]]*Fact_Sales[[#This Row],[ActualCost]]) -> 23838.81 | I12: =EOMONTH(Fact_Sales[[#This Row],[Date]],-1)+1 -> 45292 | J12: =IFERROR(Fact_Sales[[#This Row],[Quantity]]*Fact_Sales[[#This Row],[ActualCost]],0) -> 17492.19
A13: 2024-01-14 | B13: CUST-007 | C13: PRD-002 | D13: 95720.2 | E13: 188 | F13: 0.15 | G13: {=IFERROR(--SUBSTITUTE(INDEX(Product_Costing!$I$2:$I$201,MATCH(1,(Product_Costing!$B$2:$B$201=Fact_Sales[[#This Row],[ProductID]])*(Product_Costing!$C$2:$C$201=DATE(YEAR(Fact_Sales[[#This Row],[Date]]),MONTH(Fact_Sales[[#This Row],[Date]]),1)),0))&""," USD",""),"")} -> 253.51 | H13: =IF(Fact_Sales[[#This Row],[Revenue]]="","",IFERROR(--SUBSTITUTE(Fact_Sales[[#This Row],[Revenue]]&""," USD",""),Fact_Sales[[#This Row],[Revenue]])-Fact_Sales[[#This Row],[Quantity]]*Fact_Sales[[#This Row],[ActualCost]]) -> 48060.32 | I13: =EOMONTH(Fact_Sales[[#This Row],[Date]],-1)+1 -> 45292 | J13: =IFERROR(Fact_Sales[[#This Row],[Quantity]]*Fact_Sales[[#This Row],[ActualCost]],0) -> 47659.88
... A53: 2024-01-12 | B53: CUST-015 | C53: PRD-009 | D53: 76010.45 | E53: 89 | F53: 0.05 | G53: {=IFERROR(--SUBSTITUTE(INDEX(Product_Costing!$I$2:$I$201,MATCH(1,(Product_Costing!$B$2:$B$201=Fact_Sales[[#This Row],[ProductID]])*(Product_Costing!$C$2:$C$201=DATE(YEAR(Fact_Sales[[#This Row],[Date]]),MONTH(Fact_Sales[[#This Row],[Date]]),1)),0))&""," USD",""),"")} -> 358.68 | H53: =IF(Fact_Sales[[#This Row],[Revenue]]="","",IFERROR(--SUBSTITUTE(Fact_Sales[[#This Row],[Revenue]]&""," USD",""),Fact_Sales[[#This Row],[Revenue]])-Fact_Sales[[#This Row],[Quantity]]*Fact_Sales[[#This Row],[ActualCost]]) -> 44087.93 | I53: =EOMONTH(Fact_Sales[[#This Row],[Date]],-1)+1 -> 45292 | J53: =IFERROR(Fact_Sales[[#This Row],[Quantity]]*Fact_Sales[[#This Row],[ActualCost]],0) -> 31922.52
A54: 2024-01-18 | B54: CUST-005 | C54: PRD-009 | E54: 197 | F54: 0.05 | G54: {=IFERROR(--SUBSTITUTE(INDEX(Product_Costing!$I$2:$I$201,MATCH(1,(Product_Costing!$B$2:$B$201=Fact_Sales[[#This Row],[ProductID]])*(Product_Costing!$C$2:$C$201=DATE(YEAR(Fact_Sales[[#This Row],[Date]]),MONTH(Fact_Sales[[#This Row],[Date]]),1)),0))&""," USD",""),"")} -> 358.68 | H54: =IF(Fact_Sales[[#This Row],[Revenue]]="","",IFERROR(--SUBSTITUTE(Fact_Sales[[#This Row],[Revenue]]&""," USD",""),Fact_Sales[[#This Row],[Revenue]])-Fact_Sales[[#This Row],[Quantity]]*Fact_Sales[[#This Row],[ActualCost]]) | I54: =EOMONTH(Fact_Sales[[#This Row],[Date]],-1)+1 -> 45292 | J54: =IFERROR(Fact_Sales[[#This Row],[Quantity]]*Fact_Sales[[#This Row],[ActualCost]],0) -> 70659.96
A55: 2024-01-20 | B55: CUST-010 | C55: PRD-009 | D55: 28273.55 | E55: 37 | F55: 0.15 | G55: {=IFERROR(--SUBSTITUTE(INDEX(Product_Costing!$I$2:$I$201,MATCH(1,(Product_Costing!$B$2:$B$201=Fact_Sales[[#This Row],[ProductID]])*(Product_Costing!$C$2:$C$201=DATE(YEAR(Fact_Sales[[#This Row],[Date]]),MONTH(Fact_Sales[[#This Row],[Date]]),1)),0))&""," USD",""),"")} -> 358.68 | H55: =IF(Fact_Sales[[#This Row],[Revenue]]="","",IFERROR(--SUBSTITUTE(Fact_Sales[[#This Row],[Revenue]]&""," USD",""),Fact_Sales[[#This Row],[Revenue]])-Fact_Sales[[#This Row],[Quantity]]*Fact_Sales[[#This Row],[ActualCost]]) -> 15002.39 | I55: =EOMONTH(Fact_Sales[[#This Row],[Date]],-1)+1 -> 45292 | J55: =IFERROR(Fact_Sales[[#This Row],[Quantity]]*Fact_Sales[[#This Row],[ActualCost]],0) -> 13271.16
A56: 2024-01-18 | B56: CUST-012 | C56: PRD-010 | D56: -297851 | E56: 149 | F56: 0 | G56: {=IFERROR(--SUBSTITUTE(INDEX(Product_Costing!$I$2:$I$201,MATCH(1,(Product_Costing!$B$2:$B$201=Fact_Sales[[#This Row],[ProductID]])*(Product_Costing!$C$2:$C$201=DATE(YEAR(Fact_Sales[[#This Row],[Date]]),MONTH(Fact_Sales[[#This Row],[Date]]),1)),0))&""," USD",""),"")} -> 840.57 | H56: =IF(Fact_Sales[[#This Row],[Revenue]]="","",IFERROR(--SUBSTITUTE(Fact_Sales[[#This Row],[Revenue]]&""," USD",""),Fact_Sales[[#This Row],[Revenue]])-Fact_Sales[[#This Row],[Quantity]]*Fact_Sales[[#This Row],[ActualCost]]) -> -423095.93 | I56: =EOMONTH(Fact_Sales[[#This Row],[Date]],-1)+1 -> 45292 | J56: =IFERROR(Fact_Sales[[#This Row],[Quantity]]*Fact_Sales[[#This Row],[ActualCost]],0) -> 125244.93
A57: 2024-01-17 | B57: CUST-010 | C57: PRD-010 | D57: 349025.4 | E57: 194 | F57: 0.1 | G57: {=IFERROR(--SUBSTITUTE(INDEX(Product_Costing!$I$2:$I$201,MATCH(1,(Product_Costing!$B$2:$B$201=Fact_Sales[[#This Row],[ProductID]])*(Product_Costing!$C$2:$C$201=DATE(YEAR(Fact_Sales[[#This Row],[Date]]),MONTH(Fact_Sales[[#This Row],[Date]]),1)),0))&""," USD",""),"")} -> 840.57 | H57: =IF(Fact_Sales[[#This Row],[Revenue]]="","",IFERROR(--SUBSTITUTE(Fact_Sales[[#This Row],[Revenue]]&""," USD",""),Fact_Sales[[#This Row],[Revenue]])-Fact_Sales[[#This Row],[Quantity]]*Fact_Sales[[#This Row],[ActualCost]]) -> 185954.82 | I57: =EOMONTH(Fact_Sales[[#This Row],[Date]],-1)+1 -> 45292 | J57: =IFERROR(Fact_Sales[[#This Row],[Quantity]]*Fact_Sales[[#This Row],[ActualCost]],0) -> 163070.58
A58: 2024-01-23 | B58: CUST-009 | C58: PRD-010 | D58: 55972 | E58: 28 | F58: 0 | G58: {=IFERROR(--SUBSTITUTE(INDEX(Product_Costing!$I$2:$I$201,MATCH(1,(Product_Costing!$B$2:$B$201=Fact_Sales[[#This Row],[ProductID]])*(Product_Costing!$C$2:$C$201=DATE(YEAR(Fact_Sales[[#This Row],[Date]]),MONTH(Fact_Sales[[#This Row],[Date]]),1)),0))&""," USD",""),"")} -> 840.57 | H58: =IF(Fact_Sales[[#This Row],[Revenue]]="","",IFERROR(--SUBSTITUTE(Fact_Sales[[#This Row],[Revenue]]&""," USD",""),Fact_Sales[[#This Row],[Revenue]])-Fact_Sales[[#This Row],[Quantity]]*Fact_Sales[[#This Row],[ActualCost]]) -> 32436.04 | I58: =EOMONTH(Fact_Sales[[#This Row],[Date]],-1)+1 -> 45292 | J58: =IFERROR(Fact_Sales[[#This Row],[Quantity]]*Fact_Sales[[#This Row],[ActualCost]],0) -> 23535.96
A59: 2024-01-21 | B59: CUST-015 | C59: PRD-010 | D59: 96851.55 | E59: 57 | F59: 0.15 | G59: {=IFERROR(--SUBSTITUTE(INDEX(Product_Costing!$I$2:$I$201,MATCH(1,(Product_Costing!$B$2:$B$201=Fact_Sales[[#This Row],[ProductID]])*(Product_Costing!$C$2:$C$201=DATE(YEAR(Fact_Sales[[#This Row],[Date]]),MONTH(Fact_Sales[[#This Row],[Date]]),1)),0))&""," USD",""),"")} -> 840.57 | H59: =IF(Fact_Sales[[#This Row],[Revenue]]="","",IFERROR(--SUBSTITUTE(Fact_Sales[[#This Row],[Revenue]]&""," USD",""),Fact_Sales[[#This Row],[Revenue]])-Fact_Sales[[#This Row],[Quantity]]*Fact_Sales[[#This Row],[ActualCost]]) -> 48939.06 | I59: =EOMONTH(Fact_Sales[[#This Row],[Date]],-1)+1 -> 45292 | J59: =IFERROR(Fact_Sales[[#This Row],[Quantity]]*Fact_Sales[[#This Row],[ActualCost]],0) -> 47912.49
A60: 2024-01-15 | B60: CUST-011 | C60: PRD-010 | D60: 298150.85 | E60: 157 | F60: 0.05 | G60: {=IFERROR(--SUBSTITUTE(INDEX(Product_Costing!$I$2:$I$201,MATCH(1,(Product_Costing!$B$2:$B$201=Fact_Sales[[#This Row],[ProductID]])*(Product_Costing!$C$2:$C$201=DATE(YEAR(Fact_Sales[[#This Row],[Date]]),MONTH(Fact_Sales[[#This Row],[Date]]),1)),0))&""," USD",""),"")} -> 840.57 | H60: =IF(Fact_Sales[[#This Row],[Revenue]]="","",IFERROR(--SUBSTITUTE(Fact_Sales[[#This Row],[Revenue]]&""," USD",""),Fact_Sales[[#This Row],[Revenue]])-Fact_Sales[[#This Row],[Quantity]]*Fact_Sales[[#This Row],[ActualCost]]) -> 166181.36 | I60: =EOMONTH(Fact_Sales[[#This Row],[Date]],-1)+1 -> 45292 | J60: =IFERROR(Fact_Sales[[#This Row],[Quantity]]*Fact_Sales[[#This Row],[ActualCost]],0) -> 131969.49
A61: 2024-01-27 | B61: CUST-014 | C61: PRD-010 | D61: 185907 | E61: 93 | F61: 0 | G61: {=IFERROR(--SUBSTITUTE(INDEX(Product_Costing!$I$2:$I$201,MATCH(1,(Product_Costing!$B$2:$B$201=Fact_Sales[[#This Row],[ProductID]])*(Product_Costing!$C$2:$C$201=DATE(YEAR(Fact_Sales[[#This Row],[Date]]),MONTH(Fact_Sales[[#This Row],[Date]]),1)),0))&""," USD",""),"")} -> 840.57 | H61: =IF(Fact_Sales[[#This Row],[Revenue]]="","",IFERROR(--SUBSTITUTE(Fact_Sales[[#This Row],[Revenue]]&""," USD",""),Fact_Sales[[#This Row],[Revenue]])-Fact_Sales[[#This Row],[Quantity]]*Fact_Sales[[#This Row],[ActualCost]]) -> 107733.99 | I61: =EOMONTH(Fact_Sales[[#This Row],[Date]],-1)+1 -> 45292 | J61: =IFERROR(Fact_Sales[[#This Row],[Quantity]]*Fact_Sales[[#This Row],[ActualCost]],0) -> 78173.01
A62: 2024-01-28 | B62: CUST-009 | C62: PRD-011 | E62: 59 | F62: 0 | G62: {=IFERROR(--SUBSTITUTE(INDEX(Product_Costing!$I$2:$I$201,MATCH(1,(Product_Costing!$B$2:$B$201=Fact_Sales[[#This Row],[ProductID]])*(Product_Costing!$C$2:$C$201=DATE(YEAR(Fact_Sales[[#This Row],[Date]]),MONTH(Fact_Sales[[#This Row],[Date]]),1)),0))&""," USD",""),"")} -> 75.56 | H62: =IF(Fact_Sales[[#This Row],[Revenue]]="","",IFERROR(--SUBSTITUTE(Fact_Sales[[#This Row],[Revenue]]&""," USD",""),Fact_Sales[[#This Row],[Revenue]])-Fact_Sales[[#This Row],[Quantity]]*Fact_Sales[[#This Row],[ActualCost]]) | I62: =EOMONTH(Fact_Sales[[#This Row],[Date]],-1)+1 -> 45292 | J62: =IFERROR(Fact_Sales[[#This Row],[Quantity]]*Fact_Sales[[#This Row],[ActualCost]],0) -> 4458.04
A63: 2024-01-23 | B63: CUST-009 | C63: PRD-011 | D63: 3206 | E63: 14 | F63: 0 | G63: {=IFERROR(--SUBSTITUTE(INDEX(Product_Costing!$I$2:$I$201,MATCH(1,(Product_Costing!$B$2:$B$201=Fact_Sales[[#This Row],[ProductID]])*(Product_Costing!$C$2:$C$201=DATE(YEAR(Fact_Sales[[#This Row],[Date]]),MONTH(Fact_Sales[[#This Row],[Date]]),1)),0))&""," USD",""),"")} -> 75.56 | H63: =IF(Fact_Sales[[#This Row],[Revenue]]="","",IFERROR(--SUBSTITUTE(Fact_Sales[[#This Row],[Revenue]]&""," USD",""),Fact_Sales[[#This Row],[Revenue]])-Fact_Sales[[#This Row],[Quantity]]*Fact_Sales[[#This Row],[ActualCost]]) -> 2148.16 | I63: =EOMONTH(Fact_Sales[[#This Row],[Date]],-1)+1 -> 45292 | J63: =IFERROR(Fact_Sales[[#This Row],[Quantity]]*Fact_Sales[[#This Row],[ActualCost]],0) -> 1057.84
A64: 2024-01-06 | B64: CUST-007 | C64: PRD-011 | D64: 16946 | E64: 74 | F64: 0 | G64: {=IFERROR(--SUBSTITUTE(INDEX(Product_Costing!$I$2:$I$201,MATCH(1,(Product_Costing!$B$2:$B$201=Fact_Sales[[#This Row],[ProductID]])*(Product_Costing!$C$2:$C$201=DATE(YEAR(Fact_Sales[[#This Row],[Date]]),MONTH(Fact_Sales[[#This Row],[Date]]),1)),0))&""," USD",""),"")} -> 75.56 | H64: =IF(Fact_Sales[[#This Row],[Revenue]]="","",IFERROR(--SUBSTITUTE(Fact_Sales[[#This Row],[Revenue]]&""," USD",""),Fact_Sales[[#This Row],[Revenue]])-Fact_Sales[[#This Row],[Quantity]]*Fact_Sales[[#This Row],[ActualCost]]) -> 11354.56 | I64: =EOMONTH(Fact_Sales[[#This Row],[Date]],-1)+1 -> 45292 | J64: =IFERROR(Fact_Sales[[#This Row],[Quantity]]*Fact_Sales[[#This Row],[ActualCost]],0) -> 5591.44
A65: 2024-01-08 | B65: CUST-002 | C65: PRD-011 | D65: 6183 | E65: 27 | F65: 0 | G65: {=IFERROR(--SUBSTITUTE(INDEX(Product_Costing!$I$2:$I$201,MATCH(1,(Product_Costing!$B$2:$B$201=Fact_Sales[[#This Row],[ProductID]])*(Product_Costing!$C$2:$C$201=DATE(YEAR(Fact_Sales[[#This Row],[Date]]),MONTH(Fact_Sales[[#This Row],[Date]]),1)),0))&""," USD",""),"")} -> 75.56 | H65: =IF(Fact_Sales[[#This Row],[Revenue]]="","",IFERROR(--SUBSTITUTE(Fact_Sales[[#This Row],[Revenue]]&""," USD",""),Fact_Sales[[#This Row],[Revenue]])-Fact_Sales[[#This Row],[Quantity]]*Fact_Sales[[#This Row],[ActualCost]]) -> 4142.88 | I65: =EOMONTH(Fact_Sales[[#This Row],[Date]],-1)+1 -> 45292 | J65: =IFERROR(Fact_Sales[[#This Row],[Quantity]]*Fact_Sales[[#This Row],[ActualCost]],0) -> 2040.12
A66: 2024-01-23 | B66: CUST-013 | C66: PRD-011 | D66: 7980.65 | E66: 41 | F66: 0.15 | G66: {=IFERROR(--SUBSTITUTE(INDEX(Product_Costing!$I$2:$I$201,MATCH(1,(Product_Costing!$B$2:$B$201=Fact_Sales[[#This Row],[ProductID]])*(Product_Costing!$C$2:$C$201=DATE(YEAR(Fact_Sales[[#This Row],[Date]]),MONTH(Fact_Sales[[#This Row],[Date]]),1)),0))&""," USD",""),"")} -> 75.56 | H66: =IF(Fact_Sales[[#This Row],[Revenue]]="","",IFERROR(--SUBSTITUTE(Fact_Sales[[#This Row],[Revenue]]&""," USD",""),Fact_Sales[[#This Row],[Revenue]])-Fact_Sales[[#This Row],[Quantity]]*Fact_Sales[[#This Row],[ActualCost]]) -> 4882.69 | I66: =EOMONTH(Fact_Sales[[#This Row],[Date]],-1)+1 -> 45292 | J66: =IFERROR(Fact_Sales[[#This Row],[Quantity]]*Fact_Sales[[#This Row],[ActualCost]],0) -> 3097.96
A67: 2024-01-25 | B67: CUST-008 | C67: PRD-011 | D67: 41552.05 | E67: 191 | F67: 0.05 | G67: {=IFERROR(--SUBSTITUTE(INDEX(Product_Costing!$I$2:$I$201,MATCH(1,(Product_Costing!$B$2:$B$201=Fact_Sales[[#This Row],[ProductID]])*(Product_Costing!$C$2:$C$201=DATE(YEAR(Fact_Sales[[#This Row],[Date]]),MONTH(Fact_Sales[[#This Row],[Date]]),1)),0))&""," USD",""),"")} -> 75.56 | H67: =IF(Fact_Sales[[#This Row],[Revenue]]="","",IFERROR(--SUBSTITUTE(Fact_Sales[[#This Row],[Revenue]]&""," USD",""),Fact_Sales[[#This Row],[Revenue]])-Fact_Sales[[#This Row],[Quantity]]*Fact_Sales[[#This Row],[ActualCost]]) -> 27120.09 | I67: =EOMONTH(Fact_Sales[[#This Row],[Date]],-1)+1 -> 45292 | J67: =IFERROR(Fact_Sales[[#This Row],[Quantity]]*Fact_Sales[[#This Row],[ActualCost]],0) -> 14431.96
A68: 2024-01-13 | B68: CUST-005 | C68: PRD-012 | D68: 29284.2 | E68: 108 | F68: 0.15 | G68: {=IFERROR(--SUBSTITUTE(INDEX(Product_Costing!$I$2:$I$201,MATCH(1,(Product_Costing!$B$2:$B$201=Fact_Sales[[#This Row],[ProductID]])*(Product_Costing!$C$2:$C$201=DATE(YEAR(Fact_Sales[[#This Row],[Date]]),MONTH(Fact_Sales[[#This Row],[Date]]),1)),0))&""," USD",""),"")} -> 113.68 | H68: =IF(Fact_Sales[[#This Row],[Revenue]]="","",IFERROR(--SUBSTITUTE(Fact_Sales[[#This Row],[Revenue]]&""," USD",""),Fact_Sales[[#This Row],[Revenue]])-Fact_Sales[[#This Row],[Quantity]]*Fact_Sales[[#This Row],[ActualCost]]) -> 17006.76 | I68: =EOMONTH(Fact_Sales[[#This Row],[Date]],-1)+1 -> 45292 | J68: =IFERROR(Fact_Sales[[#This Row],[Quantity]]*Fact_Sales[[#This Row],[ActualCost]],0) -> 12277.44
A69: 2024-01-21 | B69: CUST-002 | C69: PRD-012 | D69: 33176 | E69: 104 | F69: 0 | G69: {=IFERROR(--SUBSTITUTE(INDEX(Product_Costing!$I$2:$I$201,MATCH(1,(Product_Costing!$B$2:$B$201=Fact_Sales[[#This Row],[ProductID]])*(Product_Costing!$C$2:$C$201=DATE(YEAR(Fact_Sales[[#This Row],[Date]]),MONTH(Fact_Sales[[#This Row],[Date]]),1)),0))&""," USD",""),"")} -> 113.68 | H69: =IF(Fact_Sales[[#This Row],[Revenue]]="","",IFERROR(--SUBSTITUTE(Fact_Sales[[#This Row],[Revenue]]&""," USD",""),Fact_Sales[[#This Row],[Revenue]])-Fact_Sales[[#This Row],[Quantity]]*Fact_Sales[[#This Row],[ActualCost]]) -> 21353.28 | I69: =EOMONTH(Fact_Sales[[#This Row],[Date]],-1)+1 -> 45292 | J69: =IFERROR(Fact_Sales[[#This Row],[Quantity]]*Fact_Sales[[#This Row],[ActualCost]],0) -> 11822.72
A70: 2024-01-11 | B70: CUST-013 | C70: PRD-012 | D70: 56973.4 | E70: 188 | F70: 0.05 | G70: {=IFERROR(--SUBSTITUTE(INDEX(Product_Costing!$I$2:$I$201,MATCH(1,(Product_Costing!$B$2:$B$201=Fact_Sales[[#This Row],[ProductID]])*(Product_Costing!$C$2:$C$201=DATE(YEAR(Fact_Sales[[#This Row],[Date]]),MONTH(Fact_Sales[[#This Row],[Date]]),1)),0))&""," USD",""),"")} -> 113.68 | H70: =IF(Fact_Sales[[#This Row],[Revenue]]="","",IFERROR(--SUBSTITUTE(Fact_Sales[[#This Row],[Revenue]]&""," USD",""),Fact_Sales[[#This Row],[Revenue]])-Fact_Sales[[#This Row],[Quantity]]*Fact_Sales[[#This Row],[ActualCost]]) -> 35601.56 | I70: =EOMONTH(Fact_Sales[[#This Row],[Date]],-1)+1 -> 45292 | J70: =IFERROR(Fact_Sales[[#This Row],[Quantity]]*Fact_Sales[[#This Row],[ActualCost]],0) -> 21371.84
A71: 2024-01-17 | B71: CUST-001 | C71: PRD-012 | D71: -3732.3 | E71: 13 | F71: 0.1 | G71: {=IFERROR(--SUBSTITUTE(INDEX(Product_Costing!$I$2:$I$201,MATCH(1,(Product_Costing!$B$2:$B$201=Fact_Sales[[#This Row],[ProductID]])*(Product_Costing!$C$2:$C$201=DATE(YEAR(Fact_Sales[[#This Row],[Date]]),MONTH(Fact_Sales[[#This Row],[Date]]),1)),0))&""," USD",""),"")} -> 113.68 | H71: =IF(Fact_Sales[[#This Row],[Revenue]]="","",IFERROR(--SUBSTITUTE(Fact_Sales[[#This Row],[Revenue]]&""," USD",""),Fact_Sales[[#This Row],[Revenue]])-Fact_Sales[[#This Row],[Quantity]]*Fact_Sales[[#This Row],[ActualCost]]) -> -5210.14 | I71: =EOMONTH(Fact_Sales[[#This Row],[Date]],-1)+1 -> 45292 | J71: =IFERROR(Fact_Sales[[#This Row],[Quantity]]*Fact_Sales[[#This Row],[ActualCost]],0) -> 1477.84
A72: 2024-01-20 | B72: CUST-010 | C72: PRD-013 | D72: 38321.4 | E72: 156 | F72: 0.15 | G72: {=IFERROR(--SUBSTITUTE(INDEX(Product_Costing!$I$2:$I$201,MATCH(1,(Product_Costing!$B$2:$B$201=Fact_Sales[[#This Row],[ProductID]])*(Product_Costing!$C$2:$C$201=DATE(YEAR(Fact_Sales[[#This Row],[Date]]),MONTH(Fact_Sales[[#This Row],[Date]]),1)),0))&""," USD",""),"")} -> 109.61 | H72: =IF(Fact_Sales[[#This Row],[Revenue]]="","",IFERROR(--SUBSTITUTE(Fact_Sales[[#This Row],[Revenue]]&""," USD",""),Fact_Sales[[#This Row],[Revenue]])-Fact_Sales[[#This Row],[Quantity]]*Fact_Sales[[#This Row],[ActualCost]]) -> 21222.24 | I72: =EOMONTH(Fact_Sales[[#This Row],[Date]],-1)+1 -> 45292 | J72: =IFERROR(Fact_Sales[[#This Row],[Quantity]]*Fact_Sales[[#This Row],[ActualCost]],0) -> 17099.16
A73: 2024-01-23 | B73: CUST-007 | C73: PRD-013 | D73: 6502.5 | E73: 25 | F73: 0.1 | G73: {=IFERROR(--SUBSTITUTE(INDEX(Product_Costing!$I$2:$I$201,MATCH(1,(Product_Costing!$B$2:$B$201=Fact_Sales[[#This Row],[ProductID]])*(Product_Costing!$C$2:$C$201=DATE(YEAR(Fact_Sales[[#This Row],[Date]]),MONTH(Fact_Sales[[#This Row],[Date]]),1)),0))&""," USD",""),"")} -> 109.61 | H73: =IF(Fact_Sales[[#This Row],[Revenue]]="","",IFERROR(--SUBSTITUTE(Fact_Sales[[#This Row],[Revenue]]&""," USD",""),Fact_Sales[[#This Row],[Revenue]])-Fact_Sales[[#This Row],[Quantity]]*Fact_Sales[[#This Row],[ActualCost]]) -> 3762.25 | I73: =EOMONTH(Fact_Sales[[#This Row],[Date]],-1)+1 -> 45292 | J73: =IFERROR(Fact_Sales[[#This Row],[Quantity]]*Fact_Sales[[#This Row],[ActualCost]],0) -> 2740.25
A74: 2024-01-08 | B74: CUST-002 | C74: PRD-013 | D74: 35373.6 | E74: 136 | F74: 0.1 | G74: {=IFERROR(--SUBSTITUTE(INDEX(Product_Costing!$I$2:$I$201,MATCH(1,(Product_Costing!$B$2:$B$201=Fact_Sales[[#This Row],[ProductID]])*(Product_Costing!$C$2:$C$201=DATE(YEAR(Fact_Sales[[#This Row],[Date]]),MONTH(Fact_Sales[[#This Row],[Date]]),1)),0))&""," USD",""),"")} -> 109.61 | H74: =IF(Fact_Sales[[#This Row],[Revenue]]="","",IFERROR(--SUBSTITUTE(Fact_Sales[[#This Row],[Revenue]]&""," USD",""),Fact_Sales[[#This Row],[Revenue]])-Fact_Sales[[#This Row],[Quantity]]*Fact_Sales[[#This Row],[ActualCost]]) -> 20466.64 | I74: =EOMONTH(Fact_Sales[[#This Row],[Date]],-1)+1 -> 45292 | J74: =IFERROR(Fact_Sales[[#This Row],[Quantity]]*Fact_Sales[[#This Row],[ActualCost]],0) -> 14906.96
... A118: 2024-02-03 | B118: CUST-013 | C118: PRD-004 | D118: 131695.65 | E118: 73 | F118: 0.05 | G118: {=IFERROR(--SUBSTITUTE(INDEX(Product_Costing!$I$2:$I$201,MATCH(1,(Product_Costing!$B$2:$B$201=Fact_Sales[[#This Row],[ProductID]])*(Product_Costing!$C$2:$C$201=DATE(YEAR(Fact_Sales[[#This Row],[Date]]),MONTH(Fact_Sales[[#This Row],[Date]]),1)),0))&""," USD",""),"")} -> 811.22 | H118: =IF(Fact_Sales[[#This Row],[Revenue]]="","",IFERROR(--SUBSTITUTE(Fact_Sales[[#This Row],[Revenue]]&""," USD",""),Fact_Sales[[#This Row],[Revenue]])-Fact_Sales[[#This Row],[Quantity]]*Fact_Sales[[#This Row],[ActualCost]]) -> 72476.59 | I118: =EOMONTH(Fact_Sales[[#This Row],[Date]],-1)+1 -> 45323 | J118: =IFERROR(Fact_Sales[[#This Row],[Quantity]]*Fact_Sales[[#This Row],[ActualCost]],0) -> 59219.06
A119: 2024-02-24 | B119: CUST-004 | C119: PRD-004 | E119: 151 | F119: 0.1 | G119: {=IFERROR(--SUBSTITUTE(INDEX(Product_Costing!$I$2:$I$201,MATCH(1,(Product_Costing!$B$2:$B$201=Fact_Sales[[#This Row],[ProductID]])*(Product_Costing!$C$2:$C$201=DATE(YEAR(Fact_Sales[[#This Row],[Date]]),MONTH(Fact_Sales[[#This Row],[Date]]),1)),0))&""," USD",""),"")} -> 811.22 | H119: =IF(Fact_Sales[[#This Row],[Revenue]]="","",IFERROR(--SUBSTITUTE(Fact_Sales[[#This Row],[Revenue]]&""," USD",""),Fact_Sales[[#This Row],[Revenue]])-Fact_Sales[[#This Row],[Quantity]]*Fact_Sales[[#This Row],[ActualCost]]) | I119: =EOMONTH(Fact_Sales[[#This Row],[Date]],-1)+1 -> 45323 | J119: =IFERROR(Fact_Sales[[#This Row],[Quantity]]*Fact_Sales[[#This Row],[ActualCost]],0) -> 122494.22
A120: 2024-02-26 | B120: CUST-001 | C120: PRD-004 | D120: 112041 | E120: 59 | F120: 0 | G120: {=IFERROR(--SUBSTITUTE(INDEX(Product_Costing!$I$2:$I$201,MATCH(1,(Product_Costing!$B$2:$B$201=Fact_Sales[[#This Row],[ProductID]])*(Product_Costing!$C$2:$C$201=DATE(YEAR(Fact_Sales[[#This Row],[Date]]),MONTH(Fact_Sales[[#This Row],[Date]]),1)),0))&""," USD",""),"")} -> 811.22 | H120: =IF(Fact_Sales[[#This Row],[Revenue]]="","",IFERROR(--SUBSTITUTE(Fact_Sales[[#This Row],[Revenue]]&""," USD",""),Fact_Sales[[#This Row],[Revenue]])-Fact_Sales[[#This Row],[Quantity]]*Fact_Sales[[#This Row],[ActualCost]]) -> 64179.02 | I120: =EOMONTH(Fact_Sales[[#This Row],[Date]],-1)+1 -> 45323 | J120: =IFERROR(Fact_Sales[[#This Row],[Quantity]]*Fact_Sales[[#This Row],[ActualCost]],0) -> 47861.98
A121: 2024-02-24 | B121: CUST-014 | C121: PRD-005 | D121: 18500.3 | E121: 26 | F121: 0.05 | G121: {=IFERROR(--SUBSTITUTE(INDEX(Product_Costing!$I$2:$I$201,MATCH(1,(Product_Costing!$B$2:$B$201=Fact_Sales[[#This Row],[ProductID]])*(Product_Costing!$C$2:$C$201=DATE(YEAR(Fact_Sales[[#This Row],[Date]]),MONTH(Fact_Sales[[#This Row],[Date]]),1)),0))&""," USD",""),"")} -> 295.58 | H121: =IF(Fact_Sales[[#This Row],[Revenue]]="","",IFERROR(--SUBSTITUTE(Fact_Sales[[#This Row],[Revenue]]&""," USD",""),Fact_Sales[[#This Row],[Revenue]])-Fact_Sales[[#This Row],[Quantity]]*Fact_Sales[[#This Row],[ActualCost]]) -> 10815.22 | I121: =EOMONTH(Fact_Sales[[#This Row],[Date]],-1)+1 -> 45323 | J121: =IFERROR(Fact_Sales[[#This Row],[Quantity]]*Fact_Sales[[#This Row],[ActualCost]],0) -> 7685.08
A122: 2024-02-15 | B122: CUST-015 | C122: PRD-005 | D122: 25466 | E122: 34 | F122: 0 | G122: {=IFERROR(--SUBSTITUTE(INDEX(Product_Costing!$I$2:$I$201,MATCH(1,(Product_Costing!$B$2:$B$201=Fact_Sales[[#This Row],[ProductID]])*(Product_Costing!$C$2:$C$201=DATE(YEAR(Fact_Sales[[#This Row],[Date]]),MONTH(Fact_Sales[[#This Row],[Date]]),1)),0))&""," USD",""),"")} -> 295.58 | H122: =IF(Fact_Sales[[#This Row],[Revenue]]="","",IFERROR(--SUBSTITUTE(Fact_Sales[[#This Row],[Revenue]]&""," USD",""),Fact_Sales[[#This Row],[Revenue]])-Fact_Sales[[#This Row],[Quantity]]*Fact_Sales[[#This Row],[ActualCost]]) -> 15416.28 | I122: =EOMONTH(Fact_Sales[[#This Row],[Date]],-1)+1 -> 45323 | J122: =IFERROR(Fact_Sales[[#This Row],[Quantity]]*Fact_Sales[[#This Row],[ActualCost]],0) -> 10049.72
...

Sheet Sales_Order
A1: SalesOrderID | B1: CustomerID | C1: OrderDate | D1: DeliveryDate | E1: Status | F1: TotalAmount
A2: SO-1000 | B2: CUST-011 | C2: 27-02-2024 | D2: 01-03-2024 | E2: delivered | F2: 157096
A3: SO-1001 | B3: CUST-002 | C3: 2024-07-13 | D3: July 19, 2024 | E3: Cancelled | F3: 149739.9
A4: SO-1002 | B4: CUST-012 | C4: 15-12-2024 | D4: 07/01/2025 | E4: Delivered | F4: 70321.35
A5: SO-1003 | B5: CUST-004 | C5: 17/01/2024 | D5: 14/02/2024 | E5: Pending | F5: 49630.65
A6: SO-1004 | B6: CUST-011 | C6: August 04, 2024 | D6: 2024-08-26 | E6: Pending
A7: SO-1005 | B7: CUST-011 | C7: June 23, 2024 | D7: June 29, 2024 | E7: Shipped | F7: 94114.45
A8: SO-1006 | B8: CUST-002 | C8: 2024-02-13 | D8: 10/03/2024 | E8: Delivered | F8: 172455.3
A9: SO-1007 | B9: CUST-003 | C9: 10/19/2024 | D9: 11/09/2024 | E9: Delivered | F9: 72284.35
A10: SO-1008 | B10: CUST-003 | C10: 27/07/2024 | D10: 14-08-2024 | E10: Cancelled
A11: SO-1009 | B11: CUST-010 | C11: 10/31/2024 | D11: 04/11/2024 | E11: Delivered | F11: 196626.15
A12: SO-1010 | B12: CUST-012 | C12: 10/10/2024 | D12: 10/17/2024 | E12: Shipped
A13: SO-1011 | B13: CUST-006 | C13: 25-10-2024 | D13: 14-11-2024 | E13: Shipped | F13: 97336
A14: SO-1012 | B14: CUST-007 | C14: 13/01/2024 | D14: 2024-01-21 | E14: Delivered | F14: 58853.7
A15: SO-1013 | B15: CUST-005 | C15: 04/01/2024 | D15: 22/04/2024 | E15: Cancelled
A16: SO-1014 | B16: CUST-002 | C16: 02-06-2024 | D16: June 21, 2024 | E16: Pending | F16: 175068.2
A17: SO-1015 | B17: CUST-005 | C17: 20-09-2024 | D17: 14/10/2024 | E17: Cancelled | F17: 180389.05
A18: SO-1016 | B18: CUST-009 | C18: 06-08-2024 | D18: 2024-09-04 | E18: Shipped | F18: 55394.75
A19: SO-1017 | B19: CUST-014 | C19: 02/08/2024 | D19: August 22, 2024 | E19: delivered | F19: 178081.9
A20: SO-1018 | B20: CUST-004 | C20: 04/12/2024 | D20: May 11, 2024 | E20: Pending | F20: 23219
A21: SO-1019 | B21: CUST-013 | C21: 24/03/2024 | E21: Pending | F21: 14364
A22: SO-1020 | B22: CUST-002 | C22: 10/16/2024 | D22: November 13, 2024 | E22: shipped | F22: 20910.45
A23: SO-1021 | B23: CUST-008 | C23: 2024-12-28 | D23: 04/01/2025 | E23: Delivered | F23: 179592.95
A24: SO-1022 | B24: CUST-013 | C24: 2024-05-03 | D24: 28/05/2024 | E24: Cancelled | F24: 85925.1
A25: SO-1023 | B25: CUST-005 | C25: April 26, 2024 | D25: 2024-05-10 | E25: DELIVERED | F25: 30362.3
A26: SO-1024 | B26: CUST-008 | C26: 02/28/2024 | D26: 28-03-2024 | E26: Cancelled | F26: 18207
A27: SO-1025 | B27: CUST-013 | C27: 2024-11-12 | D27: 11/22/2024 | E27: Delivered | F27: 375390.9
A28: SO-1026 | B28: CUST-003 | C28: June 06, 2024 | E28: Shipped | F28: 179391.25
A29: SO-1027 | B29: CUST-003 | C29: June 17, 2024 | D29: 03/07/2024 | E29: Delivered | F29: 225324.4
A30: SO-1028 | B30: CUST-014 | C30: February 28, 2024 | D30: 2024-03-16 | E30: Shipped | F30: 40745.6
A31: SO-1029 | B31: CUST-012 | C31: 2024-03-10 | D31: 04/09/2024 | E31: Cancelled | F31: 48546
A32: SO-1030 | B32: CUST-006 | C32: 19/06/2024 | D32: 07/09/2024 | E32: Delivered | F32: 69346.7
A33: SO-1031 | B33: CUST-008 | C33: 10/04/2024 | D33: 2024-10-08 | E33: Shipped | F33: 274186.15
A34: SO-1032 | B34: CUST-005 | C34: November 23, 2024 | D34: 2024-12-09 | E34: Shipped | F34: 74564.9
A35: SO-1033 | B35: CUST-006 | C35: 04/22/2024 | D35: May 15, 2024 | E35: Pending | F35: 25148.7
A36: SO-1034 | B36: CUST-003 | C36: 2024-05-11 | D36: June 09, 2024 | E36: Delivered | F36: 133756.7
A37: SO-1035 | B37: CUST-001 | C37: 20/01/2024 | D37: February 01, 2024 | E37: Delivered
A38: SO-1036 | B38: CUST-010 | C38: 2024-01-11 | D38: 15-01-2024 | E38: Delivered | F38: 58395.6
A39: SO-1037 | B39: CUST-005 | C39: 2024-01-27 | D39: 03/02/2024 | E39: cancelled | F39: 201707.95
A40: SO-1038 | B40: CUST-007 | C40: 20/02/2024 | D40: 2024-03-19 | E40: Delivered | F40: 29206.8
...

Sheet Sales_Order_Items
A1: SO_Item_ID | B1: SalesOrderID | C1: ProductID | D1: ProductName | E1: Quantity | F1: UnitPrice | G1: Discount
A2: SOI-5000 | B2: SO-1000 | C2: PRD-008 | D2: Range Hood 90cm | E2: 29 | F2: 799.0 | G2: 0
A3: SOI-5001 | B3: SO-1000 | C3: PRD-004 | E3: 70 | F3: 1899.0 | G3: 0
A4: SOI-5002 | B4: SO-1000 | C4: PRD-014 | D4: Coffee Maker Filter | E4: 5 | F4: 199.0 | G4: 0
A5: SOI-5003 | B5: SO-1001 | C5: PRD-012 | D5: toaster 4-slot | E5: 78 | F5: 319.0 | G5: 0
A6: SOI-5004 | B6: SO-1001 | C6: PRD-002 | D6: Stand Mixer 7L Professional | E6: 59 | F6: 539.1 | G6: 0.1
A7: SOI-5005 | B7: SO-1001 | C7: PRD-004 | D7: Electric Oven 90cm Built-in | E7: 49 | F7: 1899.0 | G7: 0
A8: SOI-5006 | B8: SO-1002 | C8: PRD-006 | D8: Cooktop 90cm Induction | E8: 69 | F8: 1019.15 | G8: 0.15
A9: SOI-5007 | B9: SO-1003 | C9: PRD-013 | D9: Blender Professional | E9: 35 | F9: 289.0 | G9: 0
A10: SOI-5008 | B10: SO-1003 | C10: PRD-007 | D10: Range Hood 60cm | E10: 73 | F10: 466.65 | G10: 0.15
A11: SOI-5009 | B11: SO-1003 | C11: PRD-011 | D11: Toaster 2-Slot | E11: 28 | F11: 194.65 | G11: 0.15
A12: SOI-5010 | B12: SO-1004 | C12: PRD-013 | D12: Blender Professional | E12: 49 | F12: 260.1 | G12: 0.1
A13: SOI-5011 | B13: SO-1005 | C13: PRD-014 | D13: Coffee Maker Filter | E13: 21 | F13: 189.05 | G13: 0.05
A14: SOI-5012 | B14: SO-1005 | C14: PRD-001 | D14: Stand Mixer 5L | E14: 34 | F14: 359.1 | G14: 0.1
A15: SOI-5013 | B15: SO-1005 | C15: PRD-006 | D15: Cooktop 90cm Induction | E15: 65 | F15: 1199.0 | G15: 0
... A64: SOI-5062 | B64: SO-1020 | C64: PRD-012 | D64: Toaster 4-Slot | E64: 69 | F64: 303.05 | G64: 0.05
A65: SOI-5063 | B65: SO-1021 | C65: PRD-006 | E65: 67 | F65: 1019.15 | G65: 0.15
A66: SOI-5064 | B66: SO-1021 | C66: PRD-009 | D66: Dishwasher-60cm | E66: 79 | F66: 809.1 | G66: 0.1
A67: SOI-5065 | B67: SO-1021 | C67: PRD-016 | D67: Food Processor 3L | E67: 60 | F67: 160.55 USD | G67: 0.05
A68: SOI-5066 | B68: SO-1021 | C68: PRD-009 | D68: Dishwasher 60cm | E68: 42 | F68: 899.0 | G68: 0
A69: SOI-5067 | B69: SO-1022 | C69: PRD-016 | D69: Food Processor 3L | E69: 58 | F69: 169.0 | G69: 0
A70: SOI-5068 | B70: SO-1022 | C70: PRD-003 | D70: Electric_Oven_60cm | E70: 38 | F70: 1299.0 | G70: 0
A71: SOI-5069 | B71: SO-1022 | C71: PRD-013 | D71: BLENDER PROFESSIONAL | E71: 32 | F71: 289.0 | G71: 0
A72: SOI-5070 | B72: SO-1022 | C72: PRD-012 | D72: Toaster 4-Slot | E72: 61 | F72: 287.1 | G72: 0.1
A73: SOI-5071 | B73: SO-1023 | C73: PRD-010 | D73: Refrigerator French Door | E73: 2 | F73: 1699.15 | G73: 0.15
A74: SOI-5072 | B74: SO-1023 | C74: PRD-005 | D74: Cooktop 60cm Gas | E74: 36 | F74: 749.0 | G74: 0
A75: SOI-5073 | B75: SO-1024 | C75: PRD-013 | D75: Blender Professional | E75: 63 | F75: 289.0 | G75: 0
A76: SOI-5074 | B76: SO-1025 | C76: PRD-013 | D76: blender professional | E76: 58 | F76: 274.55 | G76: 0.05
A77: SOI-5075 | B77: SO-1025 | C77: PRD-010 | D77: Refrigerator-French-Door | E77: 76 | F77: 1899.05 | G77: 0.05
... A102: SOI-5100 | B102: SO-1032 | C102: PRD-015 | D102: Coffee Maker Espresso | E102: 39 | F102: 549.0 | G102: 0
A103: SOI-5101 | B103: SO-1032 | C103: PRD-013 | E103: 62 | F103: 289.0 | G103: 0
A104: SOI-5102 | B104: SO-1032 | C104: PRD-008 | D104: Range Hood 90cm | E104: 49 | F104: 719.1 | G104: 0.1
A105: SOI-5103 | B105: SO-1033 | C105: PRD-009 | D105: Dishwasher 60cm | E105: 18 | F105: 764.15 | G105: 0.15
A106: SOI-5104 | B106: SO-1033 | C106: PRD-004 | D106: Electric Oven 90cm Built-in | E106: 6 | F106: 1899.0 | G106: 0
A107: SOI-5105 | B107: SO-1034 | C107: PRD-010 | D107: Refrigerator-French-Door | E107: 44 | F107: 1999.0 | G107: 0
A108: SOI-5106 | B108: SO-1034 | C108: PRD-015 | D108: Coffee Maker Espresso | E108: 10 | F108: 549.0 | G108: 0
A109: SOI-5107 | B109: SO-1034 | C109: PRD-008 | D109: Range Hood 90cm | E109: 51 | F109: 719.1 | G109: 0.1
A110: SOI-5108 | B110: SO-1034 | C110: PRD-012 | D110: Toaster 4-Slot | E110: 12 | F110: 303.05 | G110: 0.05
A111: SOI-5109 | B111: SO-1035 | C111: PRD-004 | D111: Electric Oven 90cm Built-in | E111: 13 | F111: 1899.0 | G111: 0
A112: SOI-5110 | B112: SO-1035 | C112: PRD-005 | D112: cooktop 60cm gas | E112: 50 | F112: 711.55 | G112: 0.05
...

Sheet GL_Transactions
A1: Column1 | B1: Column2 | C1: Column3 | D1: Column4 | E1: Column5 | F1: Column6 | G1: Column7 | H1: Column8 | I1: Column9
A2: TransactionID | B2: AccountID | C2: AccountName | D2: Amount | E2: Currency | F2: PostingDate | G2: ReferenceDocument | H2: Description | I2: =EOMONTH(GL_Transactions[[#This Row],[Column6]],-1)+1 -> #VALUE!
A3: GL-10000 | B3: ACC-4001 | C3: Utilities | D3: 66432.65 | E3: GBP | F3: January 26, 2024 | G3: REF-6493 | H3: Payroll posting | I3: =EOMONTH(GL_Transactions[[#This Row],[Column6]],-1)+1 -> 45292
A4: GL-10001 | B4: ACC-6001 | C4: Warranty Expense | D4: -28569.93 | E4: GBP | F4: 03/01/2024 | G4: REF-3255 | H4: Depreciation run | I4: =EOMONTH(GL_Transactions[[#This Row],[Column6]],-1)+1 -> 45352
A5: GL-10002 | B5: ACC-5001 | C5: Raw Material Purchases | D5: 32531.66 | E5: GBP | F5: January 10, 2024 | G5: REF-2407 | H5: Utility bill | I5: =EOMONTH(GL_Transactions[[#This Row],[Column6]],-1)+1 -> 45292
A6: GL-10003 | B6: ACC-3001 | C6: Labor Cost | D6: 68952.67 | E6: EUR | F6: 01/01/2024 | G6: REF-2596 | H6: Payroll posting | I6: =EOMONTH(GL_Transactions[[#This Row],[Column6]],-1)+1 -> 45292
A7: GL-10004 | B7: ACC-4003 | C7: Marketing | D7: -56929.51 | E7: EUR | F7: 2024-01-13 | G7: REF-2764 | H7: Freight charges | I7: =EOMONTH(GL_Transactions[[#This Row],[Column6]],-1)+1 -> 45292
A8: GL-10005 | B8: ACC-1001 | C8: Revenue | D8: 48247.77 | E8: EUR | F8: 01/15/2024 | H8: Intercompany transfer | I8: =EOMONTH(GL_Transactions[[#This Row],[Column6]],-1)+1 -> 45292
A9: GL-10006 | B9: ACC-4002 | C9: Depreciation | D9: 44004.35 | E9: EUR | F9: 2024-01-06 | G9: REF-7456 | H9: Payroll posting | I9: =EOMONTH(GL_Transactions[[#This Row],[Column6]],-1)+1 -> 45292
A10: GL-10007 | B10: ACC-4005 | C10: Admin Expenses | D10: -17262.68 | E10: EUR | F10: 2024-01-12 | G10: REF-2047 | H10: Depreciation run | I10: =EOMONTH(GL_Transactions[[#This Row],[Column6]],-1)+1 -> 45292
A11: GL-10008 | B11: ACC-4001 | C11: Utilities | D11: 17879.28 | E11: EUR | F11: 11/01/2024 | G11: REF-9154 | H11: Intercompany transfer | I11: =EOMONTH(GL_Transactions[[#This Row],[Column6]],-1)+1 -> 45597
A12: GL-10009 | B12: ACC-3001 | C12: Labor Cost | D12: 33286.23 | E12: USD | F12: 2024-01-18 | G12: REF-8169 | I12: =EOMONTH(GL_Transactions[[#This Row],[Column6]],-1)+1 -> 45292
A13: GL-10010 | B13: ACC-4004 | D13: 6838.53 | E13: GBP | F13: January 28, 2024 | G13: REF-1577 | H13: Intercompany transfer | I13: =EOMONTH(GL_Transactions[[#This Row],[Column6]],-1)+1 -> 45292
A14: GL-10011 | B14: ACC-4003 | C14: Marketing | D14: 75484.42 | E14: USD | F14: 01/20/2024 | H14: Payroll posting | I14: =EOMONTH(GL_Transactions[[#This Row],[Column6]],-1)+1 -> 45292
A15: GL-10012 | B15: ACC-3002 | C15: Overhead Cost | D15: 31617.32 | E15: EUR | F15: 2024-01-17 | G15: REF-4231 | H15: Freight charges | I15: =EOMONTH(GL_Transactions[[#This Row],[Column6]],-1)+1 -> 45292
A16: GL-10013 | B16: ACC-3001 | C16: Labor Cost | D16: 75162.27 | E16: USD | F16: 2024-01-18 | G16: REF-1172 | H16: Utility bill | I16: =EOMONTH(GL_Transactions[[#This Row],[Column6]],-1)+1 -> 45292
A17: GL-10014 | B17: ACC-1001 | C17: Revenue | D17: 56370.25 | E17: EUR | F17: 17/01/2024 | G17: REF-5391 | H17: Inventory write-off | I17: =EOMONTH(GL_Transactions[[#This Row],[Column6]],-1)+1 -> #VALUE!
A18: GL-10015 | B18: ACC-2001 | C18: Cost of Goods Sold | D18: 15998.48 | E18: EUR | F18: 03/01/2024 | H18: Freight charges | I18: =EOMONTH(GL_Transactions[[#This Row],[Column6]],-1)+1 -> 45352
A19: GL-10016 | B19: ACC-4004 | C19: Logistics | D19: 28701.52 | E19: EUR | F19: 01/09/2024 | G19: REF-6519 | H19: Inventory write-off | I19: =EOMONTH(GL_Transactions[[#This Row],[Column6]],-1)+1 -> 45292
A20: GL-10017 | B20: ACC-1001 | C20: Revenue | D20: 5710.63 | E20: USD | F20: 01/07/2024 | G20: REF-6876 | H20: Inventory write-off | I20: =EOMONTH(GL_Transactions[[#This Row],[Column6]],-1)+1 -> 45292
A21: GL-10018 | B21: ACC-4004 | C21: Logistics | D21: -43630.29 | E21: EUR | F21: 2024-01-28 | G21: REF-4201 | H21: Bonus provision | I21: =EOMONTH(GL_Transactions[[#This Row],[Column6]],-1)+1 -> 45292
A22: GL-10019 | B22: ACC-6001 | C22: Warranty Expense | D22: 53819.35 | E22: EUR | F22: January 12, 2024 | G22: REF-6192 | H22: Utility bill | I22: =EOMONTH(GL_Transactions[[#This Row],[Column6]],-1)+1 -> 45292
A23: GL-10020 | B23: ACC-4004 | C23: Logistics | D23: -40114.72 | E23: EUR | F23: 01/11/2024 | H23: Payroll posting | I23: =EOMONTH(GL_Transactions[[#This Row],[Column6]],-1)+1 -> 45292
A24: GL-10021 | B24: ACC-5001 | C24: Raw Material Purchases | D24: -32963.26 | E24: EUR | F24: 11/01/2024 | H24: Payroll posting | I24: =EOMONTH(GL_Transactions[[#This Row],[Column6]],-1)+1 -> 45597
A25: GL-10022 | B25: ACC-3002 | C25: Overhead Cost | D25: -66066.11 | E25: EUR | F25: 2024-01-07 | H25: Supplier invoice | I25: =EOMONTH(GL_Transactions[[#This Row],[Column6]],-1)+1 -> 45292
A26: GL-10023 | B26: ACC-4005 | C26: Admin Expenses | D26: 71843.89 | E26: EUR | F26: January 03, 2024 | G26: REF-2104 | H26: Payroll posting | I26: =EOMONTH(GL_Transactions[[#This Row],[Column6]],-1)+1 -> 45292
A27: GL-10024 | B27: ACC-6001 | C27: Warranty Expense | D27: 32137.65 | E27: USD | F27: 2024-01-26 | G27: REF-6504 | H27: Payroll posting | I27: =EOMONTH(GL_Transactions[[#This Row],[Column6]],-1)+1 -> 45292
A28: GL-10025 | B28: ACC-4002 | C28: Depreciation | D28: 31049.38 | E28: GBP | F28: 23/01/2024 | H28: Payroll posting | I28: =EOMONTH(GL_Transactions[[#This Row],[Column6]],-1)+1 -> #VALUE!
A29: GL-10026 | B29: ACC-4005 | C29: Admin Expenses | D29: 66262.24 | E29: EUR | F29: 20/01/2024 | G29: REF-9636 | H29: Supplier invoice | I29: =EOMONTH(GL_Transactions[[#This Row],[Column6]],-1)+1 -> #VALUE!
A30: GL-10027 | B30: ACC-3002 | C30: Overhead Cost | D30: 30138.36 | E30: USD | F30: 10/01/2024 | G30: REF-5359 | H30: Manual adjustment | I30: =EOMONTH(GL_Transactions[[#This Row],[Column6]],-1)+1 -> 45566
A31: GL-10028 | B31: ACC-4004 | C31: Logistics | D31: 58335.89 | E31: EUR | F31: 2024-01-04 | G31: REF-1807 | H31: Monthly accrual | I31: =EOMONTH(GL_Transactions[[#This Row],[Column6]],-1)+1 -> 45292
A32: GL-10029 | B32: ACC-4004 | C32: Logistics | D32: 27209.77 | E32: EUR | F32: 01/27/2024 | G32: REF-1196 | I32: =EOMONTH(GL_Transactions[[#This Row],[Column6]],-1)+1 -> 45292
A33: GL-10030 | B33: ACC-4005 | C33: Admin Expenses | D33: 76928.55 | E33: GBP | F33: 16/01/2024 | G33: REF-2300 | H33: Bonus provision | I33: =EOMONTH(GL_Transactions[[#This Row],[Column6]],-1)+1 -> #VALUE!
A34: GL-10031 | B34: ACC-4005 | C34: Admin Expenses | D34: 81178.91 | E34: USD | F34: 07-01-2024 | G34: REF-4592 | H34: Bonus provision | I34: =EOMONTH(GL_Transactions[[#This Row],[Column6]],-1)+1 -> 45474
A35: GL-10032 | B35: ACC-5001 | C35: Raw Material Purchases | D35: 35011.82 | E35: USD | F35: 07/01/2024 | G35: REF-3789 | H35: Freight charges | I35: =EOMONTH(GL_Transactions[[#This Row],[Column6]],-1)+1 -> 45474
A36: GL-10033 | B36: ACC-4002 | C36: Depreciation | D36: 543.82 | E36: EUR | F36: 2024-01-16 | I36: =EOMONTH(GL_Transactions[[#This Row],[Column6]],-1)+1 -> 45292
A37: GL-10034 | B37: ACC-4001 | C37: Utilities | D37: -1232.88 | E37: USD | F37: January 09, 2024 | G37: REF-7997 | H37: Supplier invoice | I37: =EOMONTH(GL_Transactions[[#This Row],[Column6]],-1)+1 -> 45292
A38: GL-10035 | B38: ACC-5001 | D38: 41635.61 | E38: USD | F38: 2024-01-14 | G38: REF-2881 | H38: Supplier invoice | I38: =EOMONTH(GL_Transactions[[#This Row],[Column6]],-1)+1 -> 45292
A39: GL-10036 | B39: ACC-4001 | C39: Utilities | D39: 41456.25 | E39: USD | F39: January 13, 2024 | G39: REF-6735 | H39: Intercompany transfer | I39: =EOMONTH(GL_Transactions[[#This Row],[Column6]],-1)+1 -> 45292
A40: GL-10037 | B40: ACC-5001 | C40: Raw Material Purchases | D40: 58215.2 | E40: EUR | F40: January 21, 2024 | G40: REF-9769 | H40: Intercompany transfer | I40: =EOMONTH(GL_Transactions[[#This Row],[Column6]],-1)+1 -> 45292
...

Sheet Inventory_Balance
A1: InventoryID | B1: MaterialID | C1: WarehouseID | D1: QuantityOnHand | E1: QuantityReserved | F1: QuantityAvailable | G1: LastUpdated
A2: INV-4000 | B2: MAT-001 | C2: WH-001 | D2: 1112 | E2: 12 | F2: 1100 | G2: 26-01-2024
A3: INV-4001 | B3: MAT-001 | C3: WH-001 | D3: 1343 | E3: 377 | F3: 966 | G3: February 25, 2024
A4: INV-4002 | B4: MAT-001 | C4: WH-001 | D4: 3656 | E4: 65 | G4: 26-03-2024
A5: INV-4003 | B5: MAT-001 | C5: WH-001 | D5: 4339 | E5: 1232 | G5: April 26, 2024
A6: INV-4004 | B6: MAT-001 | C6: WH-001 | D6: 3636 | E6: 451 | F6: 3185 | G6: 05/27/2024
A7: INV-4005 | B7: MAT-001 | C7: WH-001 | D7: 1507 | E7: 357 | F7: 1150 | G7: 27-06-2024
A8: INV-4006 | B8: MAT-001 | C8: WH-001 | D8: 1963 | E8: 344 | F8: 1619 | G8: 07/28/2024
A9: INV-4007 | B9: MAT-001 | C9: WH-001 | D9: 3140 | E9: 867 | F9: 2273 | G9: 08/27/2024
A10: INV-4008 | B10: MAT-001 | C10: WH-001 | D10: 3963 | E10: 1098 | F10: 2865 | G10: 09/28/2024
A11: INV-4009 | B11: MAT-001 | C11: WH-001 | D11: 4722 | E11: 600 | F11: 4122 | G11: October 27, 2024
A12: INV-4010 | B12: MAT-001 | C12: WH-001 | D12: 1775 | E12: 71 | G12: 2024-11-26
A13: INV-4011 | B13: MAT-001 | C13: WH-001 | D13: 853 | E13: 119 | F13: 734 | G13: 2024-12-28
A14: INV-4012 | B14: MAT-001 | C14: WH-002 | D14: 3914 | E14: 747 | F14: 3167 | G14: 27-01-2024
A15: INV-4013 | B15: MAT-001 | C15: WH-002 | D15: 2387 | E15: 699 | F15: 1688 | G15: February 26, 2024
A16: INV-4014 | B16: MAT-001 | C16: WH-002 | D16: 2205 | E16: 167 | F16: 2038 | G16: March 27, 2024
A17: INV-4015 | B17: MAT-001 | C17: WH-002 | D17: 1999 | E17: 332 | F17: 1667 | G17: 25-04-2024
A18: INV-4016 | B18: MAT-001 | C18: WH-002 | D18: 462 | E18: 80 | F18: 382 | G18: 25-05-2024
A19: INV-4017 | B19: MAT-001 | C19: WH-002 | D19: 4846 | E19: 644 | F19: 4202 | G19: 28/06/2024
A20: INV-4018 | B20: MAT-001 | C20: WH-002 | D20: 3958 | E20: 292 | F20: 3666 | G20: July 26, 2024
A21: INV-4019 | B21: MAT-001 | C21: WH-002 | D21: 4615 | E21: 538 | F21: 4077 | G21: August 28, 2024
A22: INV-4020 | B22: MAT-001 | C22: WH-002 | D22: 3471 | E22: 741 | F22: 2730 | G22: September 26, 2024
A23: INV-4021 | B23: MAT-001 | C23: WH-002 | D23: 4242 | E23: 186 | F23: 4056 | G23: 25-10-2024
A24: INV-4022 | B24: MAT-001 | C24: WH-002 | D24: 1510 | E24: 405 | F24: 1105 | G24: 25/11/2024
... A36: INV-4034 | B36: MAT-001 | C36: WH-003 | D36: 3788 | E36: 1059 | F36: 2729 | G36: 26-11-2024
A37: INV-4035 | B37: MAT-001 | C37: WH-003 | D37: 724 | E37: 86 | G37: December 26, 2024
A38: INV-4036 | B38: MAT-002 | C38: WH-001 | D38: 2004 | E38: 7 | G38: 25-01-2024
A39: INV-4037 | B39: MAT-002 | C39: WH-001 | D39: 752 | E39: 8 | F39: 744 | G39: February 25, 2024
A40: INV-4038 | B40: MAT-002 | C40: WH-001 | D40: 2149 | E40: 285 | F40: 1864 | G40: March 26, 2024
A41: INV-4039 | B41: MAT-002 | C41: WH-001 | D41: 1283 | E41: 370 | F41: 913 | G41: 28-04-2024
A42: INV-4040 | B42: MAT-002 | C42: WH-001 | D42: 4074 | E42: 833 | F42: 3241 | G42: 25/05/2024
A43: INV-4041 | B43: MAT-002 | C43: WH-001 | D43: 3102 | E43: 433 | F43: 2669 | G43: 06/25/2024
A44: INV-4042 | B44: MAT-002 | C44: WH-001 | D44: 696 | E44: 103 | F44: 593 | G44: 25-07-2024
A45: INV-4043 | B45: MAT-002 | C45: WH-001 | D45: 1769 | E45: 194 | F45: 1575 | G45: 26/08/2024
A46: INV-4044 | B46: MAT-002 | C46: WH-001 | D46: 1703 | E46: 142 | F46: 1561 | G46: 25/09/2024
A47: INV-4045 | B47: MAT-002 | C47: WH-001 | D47: 4708 | E47: 200 | G47: 10/25/2024
A48: INV-4046 | B48: MAT-002 | C48: WH-001 | D48: 2136 | E48: 170 | F48: 1966 | G48: 28-11-2024
A49: INV-4047 | B49: MAT-002 | C49: WH-001 | D49: 3485 | E49: 120 | F49: 3365 | G49: 25/12/2024
A50: INV-4048 | B50: MAT-002 | C50: WH-002 | D50: 2372 | E50: 465 | F50: 1907 | G50: 28-01-2024
A51: INV-4049 | B51: MAT-002 | C51: WH-002 | D51: 1755 | E51: 303 | F51: 1452 | G51: February 25, 2024
...

Sheet Inventory_Transactions
A1: Column1 | B1: Column2 | C1: Column3 | D1: Column4 | E1: Column5 | F1: Column6 | G1: Column7 | H1: Column8
A2: TransactionID | B2: MaterialID | C2: TransactionType | D2: Quantity | E2: SourceLocation | F2: DestinationLocation | G2: ReferenceDocument | H2: Timestamp
A3: IT-6000 | B3: MAT-010 | C3: Adjustment | D3: 16 | E3: External | F3: Customer | G3: REF-7653 | H3: 08/01/2024
A4: IT-6001 | B4: MAT-001 | C4: Goods Issue | D4: 226 | E4: External | F4: Production | G4: REF-6231 | H4: 2024-12-18
A5: IT-6002 | B5: MAT-003 | C5: Transfer | D5: 264 | E5: Supplier | F5: WH-001 | H5: 23/07/2024
A6: IT-6003 | B6: MAT-007 | C6: Goods Issue | D6: 493 | E6: WH-002 | F6: WH-003 | G6: REF-9433 | H6: 2024-11-11
A7: IT-6004 | B7: MAT-001 | C7: Goods Receipt | D7: 484 | E7: External | G7: REF-5609 | H7: 11/09/2024
A8: IT-6005 | B8: MAT-009 | C8: Goods Receipt | D8: 434 | E8: WH-001 | F8: Production | G8: REF-1741 | H8: May 26, 2024
A9: IT-6006 | B9: MAT-004 | C9: Transfer | D9: 284 | E9: WH-003 | F9: WH-001 | H9: 10/14/2024
A10: IT-6007 | B10: MAT-006 | C10: Transfer | D10: 286 | E10: WH-003 | G10: REF-3245 | H10: 20/07/2024
A11: IT-6008 | B11: MAT-008 | C11: Goods Issue | D11: 311 | E11: Supplier | F11: WH-002 | G11: REF-5902 | H11: September 22, 2024
A12: IT-6009 | B12: MAT-009 | C12: Return | D12: -363 | E12: Supplier | F12: WH-003 | G12: REF-7824 | H12: 09/17/2024
A13: IT-6010 | B13: MAT-008 | C13: Transfer | D13: 496 | E13: Supplier | F13: Customer | H13: 01-11-2024
A14: IT-6011 | B14: MAT-010 | C14: Adjustment | D14: 57 | E14: WH-002 | F14: WH-001 | G14: REF-9221 | H14: 17/01/2024
A15: IT-6012 | B15: MAT-003 | C15: Write-Off | D15: 107 | E15: Supplier | F15: WH-003 | G15: REF-8531 | H15: 2024-02-01
A16: IT-6013 | B16: MAT-006 | C16: Adjustment | D16: 396 | E16: WH-003 | F16: Customer | G16: REF-5876 | H16: 06-10-2024
A17: IT-6014 | B17: MAT-008 | C17: Transfer | D17: 246 | E17: WH-003 | F17: Customer | G17: REF-9899 | H17: 19/12/2024
A18: IT-6015 | B18: MAT-003 | C18: Transfer | D18: 22 | E18: WH-003 | F18: WH-001 | G18: REF-4310 | H18: 2024-06-25
A19: IT-6016 | B19: MAT-005 | C19: Goods Issue | D19: 56 | E19: Supplier | F19: Customer | H19: 14/10/2024
A20: IT-6017 | B20: MAT-008 | C20: Goods Receipt | D20: 349 | E20: WH-002 | F20: WH-001 | G20: REF-8793 | H20: 18-06-2024
A21: IT-6018 | B21: MAT-006 | C21: Transfer | D21: 331 | E21: WH-001 | F21: WH-001 | G21: REF-1611 | H21: 27-05-2024
A22: IT-6019 | B22: MAT-003 | C22: Goods Receipt | D22: 429 | E22: External | F22: Production | H22: August 01, 2024
A23: IT-6020 | B23: MAT-002 | C23: Transfer | D23: 146 | E23: External | F23: Customer | G23: REF-5470 | H23: 11/04/2024
A24: IT-6021 | B24: MAT-003 | C24: Adjustment | D24: 235 USD | E24: WH-003 | F24: WH-002 | G24: REF-4164 | H24: 18/06/2024
A25: IT-6022 | B25: MAT-009 | C25: Transfer | D25: 45 | E25: External | F25: WH-001 | G25: REF-5272 | H25: 06/08/2024
A26: IT-6023 | B26: MAT-006 | C26: Transfer | D26: 299 | E26: Supplier | F26: WH-001 | G26: REF-8625 | H26: 16/05/2024
A27: IT-6024 | B27: MAT-009 | C27: Adjustment | D27: 395 | E27: WH-003 | F27: WH-001 | G27: REF-3188 | H27: 17/12/2024
A28: IT-6025 | B28: MAT-006 | C28: Return | D28: 360 | E28: Supplier | F28: Production | G28: REF-2341 | H28: November 06, 2024
A29: IT-6026 | B29: MAT-006 | C29: Goods Receipt | D29: 470 | E29: Supplier | F29: WH-001 | G29: REF-3455 | H29: December 26, 2024
A30: IT-6027 | B30: MAT-002 | C30: Adjustment | D30: 106 | E30: Supplier | F30: Production | G30: REF-9409 | H30: August 14, 2024
A31: IT-6028 | B31: MAT-009 | C31: Return | D31: 345 | E31: WH-003 | F31: WH-001 | G31: REF-1742 | H31: 01/30/2024
A32: IT-6029 | B32: MAT-001 | C32: Goods Receipt | D32: 479 | E32: External | F32: WH-001 | G32: REF-7887 | H32: 04/10/2024
A33: IT-6030 | B33: MAT-007 | C33: Return | D33: 42 | E33: Supplier | F33: WH-002 | H33: 17-08-2024
A34: IT-6031 | B34: MAT-001 | C34: Transfer | D34: 238 | E34: Supplier | F34: Production | G34: REF-5516 | H34: 01/02/2024
A35: IT-6032 | B35: MAT-007 | C35: Write-Off | D35: 393 | F35: WH-002 | G35: REF-1797 | H35: 01/17/2024
A36: IT-6033 | B36: MAT-008 | C36: Goods Issue | D36: 277 | E36: WH-002 | F36: WH-001 | G36: REF-6224 | H36: 2024-07-24
A37: IT-6034 | B37: MAT-005 | C37: Goods Issue | D37: 339 | E37: Supplier | F37: WH-002 | G37: REF-3869 | H37: 01/05/2024
A38: IT-6035 | B38: MAT-008 | C38: Goods Receipt | D38: 498 | E38: WH-003 | F38: Production | G38: REF-7167 | H38: October 11, 2024
A39: IT-6036 | B39: MAT-004 | C39: Goods Issue | D39: 154 | E39: WH-002 | F39: Production | G39: REF-3196 | H39: 2024-08-30
A40: IT-6037 | B40: MAT-006 | C40: Adjustment | D40: 41 | E40: External | F40: WH-003 | G40: REF-1647 | H40: 14-04-2024
...

Sheet Customer
A1: CustomerID | B1: CustomerName | C1: Country | D1: Segment | E1: Channel
A2: CUST-001 | B2: Williams Sonoma | C2: USA | D2: Retailer | E2: In-Store
A3: CUST-002 | B3: Sur La Table | C3: USA | D3: Retailer | E3: In-Store
A4: CUST-003 | B4: Bed-Bath-and-Beyond | C4: USA | D4: Retailer | E4: In-Store
A5: CUST-004 | B5: Crate and Barrel | C5: USA | D5: Retailer | E5: In-Store
A6: CUST-005 | B6: Amazon | C6: USA | D6: E-Commerce | E6: Online
A7: CUST-006 | B7: Wayfair | C7: USA | D7: E-Commerce | E7: Online
A8: CUST-007 | B8: Costco-Wholesale | C8: USA | D8: Wholesale | E8: In-Store
A9: CUST-008 | B9: Target | C9: USA | D9: Retailer | E9: In-Store
A10: CUST-009 | B10: Best Buy | C10: USA | D10: Retailer | E10: In-Store
A11: CUST-010 | B11: Harvey Norman | C11: Australia | D11: Retailer | E11: In-Store
A12: CUST-011 | B12: John Lewis | C12: UK | D12: Retailer | E12: In-Store
A13: CUST-012 | B13: Fnac | C13: France | D13: Retailer
A14: CUST-013 | B14: MediaMarkt | C14: Germany | D14: Retailer | E14: In-Store
A15: CUST-014 | B15: Kitchen Direct | C15: USA | D15: Distributor | E15: B2B
A16: CUST-015 | B16: ElectroWorld | C16: Italy | D16: Retailer | E16: In-Store

Sheet Product_Master
A1: ProductID | B1: ProductCode | C1: ProductName | D1: ProductCategory | E1: ProductFamily | F1: Brand | G1: LifecycleStatus | H1: LaunchDate | I1: DiscontinueDate | J1: Voltage | K1: PowerConsumption | L1: Dimensions_Height | M1: Dimensions_Width | N1: Dimensions_Depth | O1: Weight | P1: Material | Q1: Color | R1: EnergyRating | S1: StandardCost | T1: ListPrice | U1: Currency | V1: MarginPercent | W1: HSCode | X1: CountryOfOrigin | Y1: ComplianceCertifications | Z1: ParentProductID | AA1: IsVariant
A2: PRD-001 | B2: SMG-001 | C2: Stand Mixer 5L | D2: Stand Mixers | E2: Baking | F2: SMEG | G2: Active | H2: 2018-02-21 | J2: 220V | K2: 1219W | L2: 82.5 | M2: 36.1 | N2: 44 | O2: 3.6 | P2: Stainless Steel | Q2: Silver | R2: A++ | S2: 180 | T2: 399 | U2: EUR | V2: 54.89 | W2: 8509.79 | X2: Italy | Y2: CE, RoHS, WEEE | AA2: Yes
A3: PRD-002 | B3: SMG-002 | C3: Stand Mixer 7L Professional | D3: Stand Mixers | E3: Baking | F3: SMEG | G3: Active | H3: 30/11/2021 | J3: 220V | K3: 1681W | L3: 43.6 | M3: 36.5 | N3: 29.4 | O3: 46.9 | P3: Stainless Steel | Q3: Pastel Blue | R3: B | S3: 260 | T3: 599 | U3: EUR | V3: 56.59 | X3: Italy | Y3: CE, RoHS, WEEE | Z3: PRD-001 | AA3: No
A4: PRD-003 | B4: SMG-003 | C4: Electric Oven 60cm | D4: Electric Ovens | E4: Cooking | F4: SMEG | G4: Active | H4: 12/13/2021 | J4: 220V | K4: 1985W | L4: 79.9 | M4: 90.7 | N4: 42.1 | O4: 26 | P4: Stainless Steel | Q4: Black | R4: A+ | S4: 540 | T4: 1299 | U4: EUR | V4: 58.43 | W4: 8509.44 | X4: Italy | Y4: CE, RoHS, WEEE | AA4: No
A5: PRD-004 | B5: SMG-004 | C5: Electric Oven 90cm Built-in | D5: Electric Ovens | E5: Cooking | F5: SMEG | G5: Active | H5: 01/12/2018 | J5: 220V / 110V | K5: 3081W | L5: 42.7 | M5: 83.8 | N5: 27.5 | O5: 45.6 | P5: Mixed | Q5: Black | R5: A+++ | S5: 790 | T5: 1899 | U5: EUR | V5: 58.4 | W5: 8509.82 | X5: Italy | Y5: CE, RoHS, WEEE | Z5: PRD-001 | AA5: No
A6: PRD-005 | B6: SMG-005 | C6: Cooktop 60cm Gas | D6: Cooktops | E6: Cooking | F6: SMEG | G6: Discontinued | H6: 2018-10-20 | J6: 220V / 110V | K6: 3099W | L6: 72.3 | M6: 60 | N6: 51.3 | O6: 21.2 | P6: Stainless Steel | Q6: Silver | S6: 310 | T6: 749 | U6: EUR | V6: 58.61 | W6: 8509.16 | X6: Italy | Y6: CE, RoHS, WEEE | AA6: No
A7: PRD-006 | B7: SMG-006 | C7: Cooktop 90cm Induction | D7: Cooktops | E7: Cooking | F7: SMEG | G7: Active | H7: 28/02/2020 | J7: 110V | K7: 2967W | L7: 58.7 | M7: 96 | N7: 55.6 | O7: 8.1 | P7: Aluminum | Q7: Black | R7: A+++ | S7: 490 | T7: 1199 | U7: EUR | V7: 59.13 | W7: 8509.3 | X7: Italy | Y7: CE, RoHS, WEEE | Z7: PRD-001 | AA7: No
A8: PRD-007 | B8: SMG-007 | C8: Range Hood 60cm | D8: Range Hoods | E8: Ventilation | F8: SMEG | G8: Active | H8: 11/05/2020 | I8: 45838 | J8: 110V | K8: 3417W | L8: 33.9 | M8: 56.2 | N8: 32.3 | O8: 52.5 | P8: Stainless Steel | Q8: Silver | R8: A+ | S8: 220 | T8: 549 | U8: EUR | V8: 59.93 | W8: 8509.24 | X8: Italy | Y8: CE, RoHS, WEEE | Z8: PRD-001 | AA8: No
A9: PRD-008 | B9: SMG-008 | C9: Range Hood 90cm | D9: Range Hoods | E9: Ventilation | F9: SMEG | G9: Active | H9: 29-04-2018 | I9: 45838 | J9: 220V | K9: 1150W | L9: 77.1 | M9: 98.5 | N9: 49 | O9: 8.7 | P9: Stainless Steel | Q9: Black | R9: B | S9: 330 | T9: 799 | U9: EUR | V9: 58.7 | W9: 8509.64 | X9: Italy | Y9: CE, RoHS, WEEE | Z9: PRD-001 | AA9: No
A10: PRD-009 | B10: SMG-009 | C10: Dishwasher 60cm | D10: Dishwashers | E10: Cleaning | F10: SMEG | G10: Active | H10: 2020-03-28 | J10: 220V / 110V | K10: 2649W | L10: 35.7 | M10: 53.7 | N10: 51.5 | O10: 14.2 | P10: Stainless Steel | Q10: Cream | S10: 370 | T10: 899 | U10: EUR | V10: 58.84 | W10: 8509.14 | X10: Italy | AA10: No
A11: PRD-010 | B11: SMG-010 | C11: Refrigerator French Door | D11: Refrigerators | E11: Cooling | F11: SMEG | G11: Active | H11: 09-01-2021 | I11: 45838 | J11: 220V / 110V | K11: 3160W | L11: 74.9 | M11: 86.5 | N11: 33.6 | O11: 7.1 | P11: Mixed | Q11: Pastel Blue | R11: A | S11: 850 | T11: 1999 | U11: EUR | V11: 57.48 | W11: 8509.16 | X11: Italy | Y11: CE, RoHS, WEEE | AA11: No
